Workbook

Sheet input_data
A1: 번호 | B1: 참여자 ID | C1: 방장 여부 | D1: 확인해주세요 | E1: 가능 날짜·시간 (10월) | F1: 희망 장소 | G1: 희망 메뉴 | H1: 기피 메뉴 | I1: 음주 여부
A2: 1 | B2: 조서윤2493 | C2: 방장 | E2: 10/16(금) 저녁, 10/23(금) 저녁, 10/30(금) 점심 | F2: 강남, 성수 | G2: 한식, 일식 | H2: 중식 | I2: O
A3: 2 | B3: 김민준3184 | D3: 갑각류 알레르기가 있어요 | E3: 10/16(금) 저녁, 10/22(목) 저녁, 10/23(금) 저녁 | F3: 강남, 여의도, 성수 | G3: 한식, 양식, 일식 | H3: 멕시칸 | I3: O
A4: 3 | B4: 이서현5521 | D4: 매운 음식은 잘 못 먹어요 | E4: 10/23(금) 저녁, 10/30(금) 점심 | F4: 성수, 종로 | G4: 일식, 아시안 | H4: 중식, 멕시칸 | I4: △
A5: 4 | B5: 박도윤7709 | E5: 10/16(금) 저녁, 10/22(목) 저녁, 10/23(금) 저녁 | F5: 강남, 홍대 | G5: 한식, 중식, 멕시칸 | H5: 샐러드 | I5: O
A6: 5 | B6: 최하린2046 | D6: 땅콩 알레르기가 있어요 | E6: 10/23(금) 저녁, 10/30(금) 점심 | F6: 여의도, 강남 | G6: 한식, 샐러드, 일식 | H6: 중식 | I6: X
A7: 6 | B7: 정우진8832 | E7: 10/16(금) 저녁, 10/22(목) 저녁, 10/23(금) 저녁, 10/24(토) 저녁 | F7: 강남, 성수, 이태원 | G7: 한식, 양식 | H7: 아시안 | I7: O
A8: 7 | B8: 강지아4415 | D8: 우유가 들어간 음식은 피하고 있어요 | E8: 10/16(금) 저녁, 10/23(금) 저녁 | F8: 성수, 종로 | G8: 아시안, 일식 | H8: 양식, 중식 | I8: △
A9: 8 | B9: 윤시우6290 | E9: 10/22(목) 저녁, 10/23(금) 저녁, 10/30(금) 점심 | F9: 종로, 강남 | G9: 한식, 아시안, 멕시칸 | H9: 샐러드 | I9: O
A10: 9 | B10: 한예린1357 | D10: 마라탕은 못 먹어요 | E10: 10/16(금) 저녁, 10/23(금) 저녁 | F10: 성수, 여의도, 문래 | G10: 한식, 일식, 양식 | H10: 중식, 멕시칸 | I10: △
A11: 10 | B11: 오지훈9064 | D11: 조개류 알레르기가 있어요 | E11: 10/16(금) 저녁, 10/23(금) 저녁, 10/31(토) 점심 | F11: 강남, 용산 | G11: 한식, 중식 | H11: 아시안 | I11: X
A13: ※ 모든 데이터는 테스트용 가상 데이터입니다. (이름·숫자·알레르기 정보는 실제 인물과 무관)
A14: ※ 파란 글자 칸이 입력값입니다. 값을 바꾸면 '집계(검증용)' 시트가 자동으로 다시 계산됩니다.
A15: ※ 날짜·시간 형식: 10/23(금) 저녁 (쉼표로 구분, 시간대는 점심·저녁만) / 장소·메뉴는 '모집단' 시트의 항목만, 각 최대 3개
A16: ※ 음주 여부는 O, △, X 중 하나 / 확인해주세요는 비워도 됩니다.
A17: ※ 시연 포인트: 10/23(금) 저녁 만장일치, 날짜·장소·메뉴 모두 '공동 3위' 발생, 확인해주세요 6건(알레르기 4 + 매운 음식 + 마라탕)
A18: ※ 조서윤2493은 방장이며, 초대 링크로 입장해 다른 참여자와 똑같이 투표한 것으로 가정합니다.

Sheet 모집단
A1: 구분 | B1: 항목 | C1: 비고
A2: 장소 | B2: 강남
A3: 장소 | B3: 잠실
A4: 장소 | B4: 여의도
A5: 장소 | B5: 성수
A6: 장소 | B6: 종로
A7: 장소 | B7: 홍대
A8: 장소 | B8: 용산
A9: 장소 | B9: 이태원
A10: 장소 | B10: 문래
A11: 메뉴 | B11: 한식
A12: 메뉴 | B12: 중식
A13: 메뉴 | B13: 양식
... A19: 시간대 | B19: 저녁
A20: 음주 | B20: O | C20: 오늘은 달려봐요! 끝까지 함께할게요 🍻
A21: 음주 | B21: △ | C21: 분위기 보고 가볍게 한두 잔 할게요
A22: 음주 | B22: X | C22: 오늘은 쉬어갈게요. 음료로 건배해요 🥤
A24: 세부 메뉴 예시 DB (성준님 DB로 교체 예정 · 괄호는 주의 재료)
A25: 카테고리 | B25: 세부 메뉴 | C25: 주의 재료
A26: 한식 | B26: 보쌈
A27: 한식 | B27: 김치찌개 | C27: 매운
A28: 한식 | B28: 닭갈비 | C28: 밀, 매운
A29: 한식 | B29: 비빔밥 | C29: 계란
A30: 한식 | B30: 해물파전 | C30: 갑각류, 조개류, 밀, 계란
A31: 중식 | B31: 짜장면 | C31: 밀
A32: 중식 | B32: 마라탕 | C32: 땅콩, 밀, 매운
A33: 중식 | B33: 탕수육 | C33: 밀, 계란
A34: 중식 | B34: 딤섬 | C34: 밀, 갑각류
A35: 양식 | B35: 스테이크
A36: 양식 | B36: 파스타 | C36: 밀, 우유
A37: 양식 | B37: 리조또 | C37: 우유
A38: 양식 | B38: 피자 | C38: 밀, 우유
A39: 일식 | B39: 규동
A40: 일식 | B40: 초밥 | C40: 갑각류, 조개류
A41: 일식 | B41: 돈카츠 | C41: 밀, 계란
A42: 일식 | B42: 라멘 | C42: 밀, 계란
A43: 아시안 | B43: 쌀국수
A44: 아시안 | B44: 분짜 | C44: 땅콩
A45: 아시안 | B45: 팟타이 | C45: 땅콩, 갑각류, 계란
A46: 아시안 | B46: 똠얌꿍 | C46: 갑각류, 매운
...

Sheet 집계(검증용)
A1: 총 참여 인원 | B1: =COUNTA(input_data!B2:B11) -> 10 | D1: ※ 앱 랭킹 로직 검증용 정답지입니다. 순위는 동률이면 같은 순위('공동')이고, 다음 순위는 건너뜁니다.
A3: 날짜·시간 | B3: 표 수 | C3: 순위 | D3: 순위 표기 | E3: 만장일치
A4: 10/16(금) 저녁 | B4: =COUNTIF(input_data!$E$2:$E$11,"*"&A4&"*") -> 7 | C4: =IF(B4=0,"-",RANK(B4,$B$4:$B$9)) -> 2 | D4: =IF(B4=0,"",IF(C4>3,"",IF(COUNTIF($B$4:$B$9,B4)>1,"공동 ","")&C4&"위")) -> 2위 | E4: =IF(B4=$B$1,"만장일치","")
A5: 10/22(목) 저녁 | B5: =COUNTIF(input_data!$E$2:$E$11,"*"&A5&"*") -> 4 | C5: =IF(B5=0,"-",RANK(B5,$B$4:$B$9)) -> 3 | D5: =IF(B5=0,"",IF(C5>3,"",IF(COUNTIF($B$4:$B$9,B5)>1,"공동 ","")&C5&"위")) -> 공동 3위 | E5: =IF(B5=$B$1,"만장일치","")
A6: 10/23(금) 저녁 | B6: =COUNTIF(input_data!$E$2:$E$11,"*"&A6&"*") -> 10 | C6: =IF(B6=0,"-",RANK(B6,$B$4:$B$9)) -> 1 | D6: =IF(B6=0,"",IF(C6>3,"",IF(COUNTIF($B$4:$B$9,B6)>1,"공동 ","")&C6&"위")) -> 1위 | E6: =IF(B6=$B$1,"만장일치","") -> 만장일치
A7: 10/24(토) 저녁 | B7: =COUNTIF(input_data!$E$2:$E$11,"*"&A7&"*") -> 1 | C7: =IF(B7=0,"-",RANK(B7,$B$4:$B$9)) -> 5 | D7: =IF(B7=0,"",IF(C7>3,"",IF(COUNTIF($B$4:$B$9,B7)>1,"공동 ","")&C7&"위")) | E7: =IF(B7=$B$1,"만장일치","")
A8: 10/30(금) 점심 | B8: =COUNTIF(input_data!$E$2:$E$11,"*"&A8&"*") -> 4 | C8: =IF(B8=0,"-",RANK(B8,$B$4:$B$9)) -> 3 | D8: =IF(B8=0,"",IF(C8>3,"",IF(COUNTIF($B$4:$B$9,B8)>1,"공동 ","")&C8&"위")) -> 공동 3위 | E8: =IF(B8=$B$1,"만장일치","")
A9: 10/31(토) 점심 | B9: =COUNTIF(input_data!$E$2:$E$11,"*"&A9&"*") -> 1 | C9: =IF(B9=0,"-",RANK(B9,$B$4:$B$9)) -> 5 | D9: =IF(B9=0,"",IF(C9>3,"",IF(COUNTIF($B$4:$B$9,B9)>1,"공동 ","")&C9&"위")) | E9: =IF(B9=$B$1,"만장일치","")
A11: 희망 장소 | B11: 표 수 | C11: 순위 | D11: 순위 표기
A12: 강남 | B12: =COUNTIF(input_data!$F$2:$F$11,"*"&A12&"*") -> 7 | C12: =IF(B12=0,"-",RANK(B12,$B$12:$B$20)) -> 1 | D12: =IF(B12=0,"",IF(C12>3,"",IF(COUNTIF($B$12:$B$20,B12)>1,"공동 ","")&C12&"위")) -> 1위
A13: 잠실 | B13: =COUNTIF(input_data!$F$2:$F$11,"*"&A13&"*") -> 0 | C13: =IF(B13=0,"-",RANK(B13,$B$12:$B$20)) -> - | D13: =IF(B13=0,"",IF(C13>3,"",IF(COUNTIF($B$12:$B$20,B13)>1,"공동 ","")&C13&"위"))
A14: 여의도 | B14: =COUNTIF(input_data!$F$2:$F$11,"*"&A14&"*") -> 3 | C14: =IF(B14=0,"-",RANK(B14,$B$12:$B$20)) -> 3 | D14: =IF(B14=0,"",IF(C14>3,"",IF(COUNTIF($B$12:$B$20,B14)>1,"공동 ","")&C14&"위")) -> 공동 3위
A15: 성수 | B15: =COUNTIF(input_data!$F$2:$F$11,"*"&A15&"*") -> 6 | C15: =IF(B15=0,"-",RANK(B15,$B$12:$B$20)) -> 2 | D15: =IF(B15=0,"",IF(C15>3,"",IF(COUNTIF($B$12:$B$20,B15)>1,"공동 ","")&C15&"위")) -> 2위
A16: 종로 | B16: =COUNTIF(input_data!$F$2:$F$11,"*"&A16&"*") -> 3 | C16: =IF(B16=0,"-",RANK(B16,$B$12:$B$20)) -> 3 | D16: =IF(B16=0,"",IF(C16>3,"",IF(COUNTIF($B$12:$B$20,B16)>1,"공동 ","")&C16&"위")) -> 공동 3위
A17: 홍대 | B17: =COUNTIF(input_data!$F$2:$F$11,"*"&A17&"*") -> 1 | C17: =IF(B17=0,"-",RANK(B17,$B$12:$B$20)) -> 5 | D17: =IF(B17=0,"",IF(C17>3,"",IF(COUNTIF($B$12:$B$20,B17)>1,"공동 ","")&C17&"위"))
A18: 용산 | B18: =COUNTIF(input_data!$F$2:$F$11,"*"&A18&"*") -> 1 | C18: =IF(B18=0,"-",RANK(B18,$B$12:$B$20)) -> 5 | D18: =IF(B18=0,"",IF(C18>3,"",IF(COUNTIF($B$12:$B$20,B18)>1,"공동 ","")&C18&"위"))
A19: 이태원 | B19: =COUNTIF(input_data!$F$2:$F$11,"*"&A19&"*") -> 1 | C19: =IF(B19=0,"-",RANK(B19,$B$12:$B$20)) -> 5 | D19: =IF(B19=0,"",IF(C19>3,"",IF(COUNTIF($B$12:$B$20,B19)>1,"공동 ","")&C19&"위"))
A20: 문래 | B20: =COUNTIF(input_data!$F$2:$F$11,"*"&A20&"*") -> 1 | C20: =IF(B20=0,"-",RANK(B20,$B$12:$B$20)) -> 5 | D20: =IF(B20=0,"",IF(C20>3,"",IF(COUNTIF($B$12:$B$20,B20)>1,"공동 ","")&C20&"위"))
A22: 희망 메뉴(좋아요) | B22: 표 수 | C22: 순위 | D22: 순위 표기
A23: 한식 | B23: =COUNTIF(input_data!$G$2:$G$11,"*"&A23&"*") -> 8 | C23: =IF(B23=0,"-",RANK(B23,$B$23:$B$29)) -> 1 | D23: =IF(B23=0,"",IF(C23>3,"",IF(COUNTIF($B$23:$B$29,B23)>1,"공동 ","")&C23&"위")) -> 1위
A24: 중식 | B24: =COUNTIF(input_data!$G$2:$G$11,"*"&A24&"*") -> 2 | C24: =IF(B24=0,"-",RANK(B24,$B$23:$B$29)) -> 5 | D24: =IF(B24=0,"",IF(C24>3,"",IF(COUNTIF($B$23:$B$29,B24)>1,"공동 ","")&C24&"위"))
A25: 양식 | B25: =COUNTIF(input_data!$G$2:$G$11,"*"&A25&"*") -> 3 | C25: =IF(B25=0,"-",RANK(B25,$B$23:$B$29)) -> 3 | D25: =IF(B25=0,"",IF(C25>3,"",IF(COUNTIF($B$23:$B$29,B25)>1,"공동 ","")&C25&"위")) -> 공동 3위
A26: 일식 | B26: =COUNTIF(input_data!$G$2:$G$11,"*"&A26&"*") -> 6 | C26: =IF(B26=0,"-",RANK(B26,$B$23:$B$29)) -> 2 | D26: =IF(B26=0,"",IF(C26>3,"",IF(COUNTIF($B$23:$B$29,B26)>1,"공동 ","")&C26&"위")) -> 2위
A27: 아시안 | B27: =COUNTIF(input_data!$G$2:$G$11,"*"&A27&"*") -> 3 | C27: =IF(B27=0,"-",RANK(B27,$B$23:$B$29)) -> 3 | D27: =IF(B27=0,"",IF(C27>3,"",IF(COUNTIF($B$23:$B$29,B27)>1,"공동 ","")&C27&"위")) -> 공동 3위
A28: 멕시칸 | B28: =COUNTIF(input_data!$G$2:$G$11,"*"&A28&"*") -> 2 | C28: =IF(B28=0,"-",RANK(B28,$B$23:$B$29)) -> 5 | D28: =IF(B28=0,"",IF(C28>3,"",IF(COUNTIF($B$23:$B$29,B28)>1,"공동 ","")&C28&"위"))
A29: 샐러드 | B29: =COUNTIF(input_data!$G$2:$G$11,"*"&A29&"*") -> 1 | C29: =IF(B29=0,"-",RANK(B29,$B$23:$B$29)) -> 7 | D29: =IF(B29=0,"",IF(C29>3,"",IF(COUNTIF($B$23:$B$29,B29)>1,"공동 ","")&C29&"위"))
A31: 기피 메뉴(싫어요) | B31: 표 수 | C31: 순위 | D31: 순위 표기
A32: 한식 | B32: =COUNTIF(input_data!$H$2:$H$11,"*"&A32&"*") -> 0 | C32: =IF(B32=0,"-",RANK(B32,$B$32:$B$38)) -> - | D32: =IF(B32=0,"",IF(C32>3,"",IF(COUNTIF($B$32:$B$38,B32)>1,"공동 ","")&C32&"위"))
A33: 중식 | B33: =COUNTIF(input_data!$H$2:$H$11,"*"&A33&"*") -> 5 | C33: =IF(B33=0,"-",RANK(B33,$B$32:$B$38)) -> 1 | D33: =IF(B33=0,"",IF(C33>3,"",IF(COUNTIF($B$32:$B$38,B33)>1,"공동 ","")&C33&"위")) -> 1위
A34: 양식 | B34: =COUNTIF(input_data!$H$2:$H$11,"*"&A34&"*") -> 1 | C34: =IF(B34=0,"-",RANK(B34,$B$32:$B$38)) -> 5 | D34: =IF(B34=0,"",IF(C34>3,"",IF(COUNTIF($B$32:$B$38,B34)>1,"공동 ","")&C34&"위"))
A35: 일식 | B35: =COUNTIF(input_data!$H$2:$H$11,"*"&A35&"*") -> 0 | C35: =IF(B35=0,"-",RANK(B35,$B$32:$B$38)) -> - | D35: =IF(B35=0,"",IF(C35>3,"",IF(COUNTIF($B$32:$B$38,B35)>1,"공동 ","")&C35&"위"))
A36: 아시안 | B36: =COUNTIF(input_data!$H$2:$H$11,"*"&A36&"*") -> 2 | C36: =IF(B36=0,"-",RANK(B36,$B$32:$B$38)) -> 3 | D36: =IF(B36=0,"",IF(C36>3,"",IF(COUNTIF($B$32:$B$38,B36)>1,"공동 ","")&C36&"위")) -> 공동 3위
A37: 멕시칸 | B37: =COUNTIF(input_data!$H$2:$H$11,"*"&A37&"*") -> 3 | C37: =IF(B37=0,"-",RANK(B37,$B$32:$B$38)) -> 2 | D37: =IF(B37=0,"",IF(C37>3,"",IF(COUNTIF($B$32:$B$38,B37)>1,"공동 ","")&C37&"위")) -> 2위
A38: 샐러드 | B38: =COUNTIF(input_data!$H$2:$H$11,"*"&A38&"*") -> 2 | C38: =IF(B38=0,"-",RANK(B38,$B$32:$B$38)) -> 3 | D38: =IF(B38=0,"",IF(C38>3,"",IF(COUNTIF($B$32:$B$38,B38)>1,"공동 ","")&C38&"위")) -> 공동 3위
A40: 음주 | B40: 표 수
A41: O | B41: =COUNTIF(input_data!$I$2:$I$11,A41) -> 5
A42: △ | B42: =COUNTIF(input_data!$I$2:$I$11,A42) -> 3
A43: X | B43: =COUNTIF(input_data!$I$2:$I$11,A43) -> 2
A45: 확인해주세요 건수 | B45: =COUNTIF(input_data!$D$2:$D$11,"?*") -> 6

Sheet 결과요약(정답)
A1: 앱의 [단톡방에 공유하기]로 복사되는 텍스트 정답 (현재 입력값 기준)
A3: [콘텐츠팀 회식] 모임 결과 요약 (10명 참여)
A5: 날짜
A6: 1위 10/23(금) 저녁 (10표) [만장일치]
A7: 2위 10/16(금) 저녁 (7표)
A8: 공동 3위 10/22(목) 저녁 · 10/30(금) 점심 (4표)
A9: 장소
A10: 1위 강남 (7표)
A11: 2위 성수 (6표)
A12: 공동 3위 여의도 · 종로 (3표)
A13: 메뉴
A14: 좋아요 한식, 일식
... A21: ※ 입력값을 바꾸면 이 시트는 자동으로 바뀌지 않습니다. 집계(검증용) 시트를 기준으로 다시 확인해 주세요.
